Workbook

Sheet Notes
A1: Music Collection Wishlist (rebuilt)
A3: Rebuilt on 3 Oct 2026 from the data embedded in the "Collection Shape" artifact (https://claude.ai/artifact/UvuYBeCfaw71KNLewGKJKn), dated 16 Sep 2026.
A4: The original Music Collection Wishlist.xlsx was not available, so this is a reconstruction, not the original file.
A6: Albums tab: one row per album (1,541 rows). Edit the Owned column (Yes/No) as your library changes; the By Family and By Style tabs recalculate from it.
A7: Tier: 1, 2, 3 = the ranking from the original list (1 = most essential). "Library" = albums you owned that were added from the Pi rather than from the ranked list.
A8: Owned: matched by folder names on /mnt/ssd1/data/media/music on 16 Sep 2026; matching by file tags would be more accurate.
A9: Origin is blank where the source data did not record one.
A10: Want List: 18 Tier 1 albums not owned, ranked by how much you already collect in each style, max two per style (as in the artifact). It does not update automatically.
A11: Not recoverable from the artifact: per-album release type (Album / EP / Compilation / Soundtrack) and any other columns the original sheet may have had.

Sheet Albums
A1: Family | B1: Style | C1: Artist | D1: Album | E1: Year | F1: Origin | G1: Tier | H1: Owned
A2: Rock | B2: Alternative & Indie Rock | C2: Ganso | D2: Costela Ofendida | E2: 2015 | F2: Portugal | G2: Library | H2: Yes
A3: Rock | B3: Alternative & Indie Rock | C3: Ganso | D3: Pá Pá Pá | E3: 2017 | F3: Portugal | G3: Library | H3: Yes
A4: Rock | B4: Alternative & Indie Rock | C4: Ganso | D4: Não Tarda | E4: 2019 | F4: Portugal | G4: Library | H4: Yes
A5: Rock | B5: Alternative & Indie Rock | C5: Ganso | D5: Vice Versa | E5: 2024 | F5: Portugal | G5: Library | H5: Yes
A6: Rock | B6: Alternative & Indie Rock | C6: Cassete Pirata | D6: A Montra | E6: 2019 | F6: Portugal | G6: Library | H6: Yes
A7: Rock | B7: Alternative & Indie Rock | C7: Cassete Pirata | D7: A Semente | E7: 2021 | F7: Portugal | G7: Library | H7: Yes
A8: Rock | B8: Alternative & Indie Rock | C8: Cassete Pirata | D8: A Família | E8: 2024 | F8: Portugal | G8: Library | H8: Yes
A9: Rock | B9: Alternative & Indie Rock | C9: Franz Ferdinand | D9: Franz Ferdinand | E9: 2004 | F9: UK (Scotland) | G9: Library | H9: Yes
A10: Rock | B10: Alternative & Indie Rock | C10: Franz Ferdinand | D10: You Could Have It So Much Better | E10: 2005 | F10: UK (Scotland) | G10: Library | H10: Yes
A11: Rock | B11: Alternative & Indie Rock | C11: Franz Ferdinand | D11: Tonight | E11: 2009 | F11: UK (Scotland) | G11: Library | H11: Yes
A12: Rock | B12: Alternative & Indie Rock | C12: Pixies | D12: Surfer Rosa | E12: 1988 | G12: 1 | H12: Yes
A13: Rock | B13: Alternative & Indie Rock | C13: Pixies | D13: Doolittle | E13: 1989 | G13: 1 | H13: Yes
A14: Rock | B14: Alternative & Indie Rock | C14: Pixies | D14: Bossanova | E14: 1990 | G14: 3 | H14: Yes
A15: Rock | B15: Alternative & Indie Rock | C15: Radiohead | D15: OK Computer | E15: 1997 | G15: 1 | H15: Yes
A16: Rock | B16: Alternative & Indie Rock | C16: Radiohead | D16: Kid A | E16: 2000 | G16: 1 | H16: Yes
A17: Rock | B17: Alternative & Indie Rock | C17: Radiohead | D17: In Rainbows | E17: 2007 | G17: 1 | H17: Yes
A18: Rock | B18: Alternative & Indie Rock | C18: Radiohead | D18: The Bends | E18: 1995 | G18: 2 | H18: No
A19: Rock | B19: Alternative & Indie Rock | C19: Radiohead | D19: Amnesiac | E19: 2001 | G19: 2 | H19: No
A20: Rock | B20: Alternative & Indie Rock | C20: Radiohead | D20: A Moon Shaped Pool | E20: 2016 | G20: 2 | H20: No
A21: Rock | B21: Alternative & Indie Rock | C21: Radiohead | D21: Hail to the Thief | E21: 2003 | G21: 3 | H21: No
A22: Rock | B22: Alternative & Indie Rock | C22: Saint Motel | D22: Voyeur | E22: 2012 | G22: Library | H22: Yes
A23: Rock | B23: Alternative & Indie Rock | C23: Saint Motel | D23: My Type EP | E23: 2014 | G23: Library | H23: Yes
A24: Rock | B24: Alternative & Indie Rock | C24: Saint Motel | D24: saintmotelevision | E24: 2016 | G24: Library | H24: Yes
A25: Rock | B25: Alternative & Indie Rock | C25: Vampire Weekend | D25: Modern Vampires of the City | E25: 2013 | G25: Library | H25: Yes
A26: Rock | B26: Alternative & Indie Rock | C26: Vampire Weekend | D26: Father of the Bride | E26: 2019 | G26: Library | H26: Yes
A27: Rock | B27: Alternative & Indie Rock | C27: Vampire Weekend | D27: Only God Was Above Us | E27: 2024 | G27: Library | H27: Yes
A28: Rock | B28: Alternative & Indie Rock | C28: Zanibar Aliens | D28: Space Pigeon | E28: 2017 | F28: Portugal | G28: Library | H28: Yes
A29: Rock | B29: Alternative & Indie Rock | C29: Zanibar Aliens | D29: Zanibar Aliens III | E29: 2019 | F29: Portugal | G29: Library | H29: Yes
A30: Rock | B30: Alternative & Indie Rock | C30: Zanibar Aliens | D30: IV | E30: 2020 | F30: Portugal | G30: Library | H30: Yes
A31: Rock | B31: Alternative & Indie Rock | C31: alt-J | D31: Relaxer | E31: 2017 | F31: UK | G31: Library | H31: Yes
A32: Rock | B32: Alternative & Indie Rock | C32: alt-J | D32: The Dream | E32: 2022 | F32: UK | G32: Library | H32: Yes
A33: Rock | B33: Alternative & Indie Rock | C33: Arctic Monkeys | D33: Whatever People Say I Am, That's What I'm Not | E33: 2006 | F33: UK | G33: Library | H33: Yes
A34: Rock | B34: Alternative & Indie Rock | C34: Arctic Monkeys | D34: Favourite Worst Nightmare | E34: 2007 | F34: UK | G34: Library | H34: Yes
A35: Rock | B35: Alternative & Indie Rock | C35: Cage The Elephant | D35: Melophobia | E35: 2013 | G35: Library | H35: Yes
A36: Rock | B36: Alternative & Indie Rock | C36: Cage The Elephant | D36: Tell Me I'm Pretty | E36: 2015 | G36: Library | H36: Yes
A37: Rock | B37: Alternative & Indie Rock | C37: Capitão Fausto | D37: Gazela | E37: 2011 | F37: Portugal | G37: Library | H37: Yes
A38: Rock | B38: Alternative & Indie Rock | C38: Capitão Fausto | D38: Capitão Fausto Têm os Dias Contados | E38: 2016 | F38: Portugal | G38: Library | H38: Yes
A39: Rock | B39: Alternative & Indie Rock | C39: Carl Karlsson | D39: Ås | E39: 2023 | F39: Portugal | G39: Library | H39: Yes
A40: Rock | B40: Alternative & Indie Rock | C40: Carl Karlsson | D40: Caminhos | E40: 2025 | F40: Portugal | G40: Library | H40: Yes
...

Sheet By Family
A1: Family | B1: Albums in list | C1: Owned | D1: Missing | E1: % owned
A2: Rock | B2: =COUNTIF(Albums!$A$2:$A$1542,A2) | C2: =COUNTIFS(Albums!$A$2:$A$1542,A2,Albums!$H$2:$H$1542,"Yes") | D2: =B2-C2 | E2: =IF(B2=0,0,C2/B2)
A3: Pop | B3: =COUNTIF(Albums!$A$2:$A$1542,A3) | C3: =COUNTIFS(Albums!$A$2:$A$1542,A3,Albums!$H$2:$H$1542,"Yes") | D3: =B3-C3 | E3: =IF(B3=0,0,C3/B3)
A4: Hip-Hop | B4: =COUNTIF(Albums!$A$2:$A$1542,A4) | C4: =COUNTIFS(Albums!$A$2:$A$1542,A4,Albums!$H$2:$H$1542,"Yes") | D4: =B4-C4 | E4: =IF(B4=0,0,C4/B4)
A5: Latin | B5: =COUNTIF(Albums!$A$2:$A$1542,A5) | C5: =COUNTIFS(Albums!$A$2:$A$1542,A5,Albums!$H$2:$H$1542,"Yes") | D5: =B5-C5 | E5: =IF(B5=0,0,C5/B5)
A6: Electronic | B6: =COUNTIF(Albums!$A$2:$A$1542,A6) | C6: =COUNTIFS(Albums!$A$2:$A$1542,A6,Albums!$H$2:$H$1542,"Yes") | D6: =B6-C6 | E6: =IF(B6=0,0,C6/B6)
A7: Folk, World & Country | B7: =COUNTIF(Albums!$A$2:$A$1542,A7) | C7: =COUNTIFS(Albums!$A$2:$A$1542,A7,Albums!$H$2:$H$1542,"Yes") | D7: =B7-C7 | E7: =IF(B7=0,0,C7/B7)
A8: Jazz | B8: =COUNTIF(Albums!$A$2:$A$1542,A8) | C8: =COUNTIFS(Albums!$A$2:$A$1542,A8,Albums!$H$2:$H$1542,"Yes") | D8: =B8-C8 | E8: =IF(B8=0,0,C8/B8)
A9: Funk / Soul / R&B | B9: =COUNTIF(Albums!$A$2:$A$1542,A9) | C9: =COUNTIFS(Albums!$A$2:$A$1542,A9,Albums!$H$2:$H$1542,"Yes") | D9: =B9-C9 | E9: =IF(B9=0,0,C9/B9)
A10: Blues | B10: =COUNTIF(Albums!$A$2:$A$1542,A10) | C10: =COUNTIFS(Albums!$A$2:$A$1542,A10,Albums!$H$2:$H$1542,"Yes") | D10: =B10-C10 | E10: =IF(B10=0,0,C10/B10)
A11: Metal | B11: =COUNTIF(Albums!$A$2:$A$1542,A11) | C11: =COUNTIFS(Albums!$A$2:$A$1542,A11,Albums!$H$2:$H$1542,"Yes") | D11: =B11-C11 | E11: =IF(B11=0,0,C11/B11)
A12: Reggae & Dub | B12: =COUNTIF(Albums!$A$2:$A$1542,A12) | C12: =COUNTIFS(Albums!$A$2:$A$1542,A12,Albums!$H$2:$H$1542,"Yes") | D12: =B12-C12 | E12: =IF(B12=0,0,C12/B12)
A13: Classical | B13: =COUNTIF(Albums!$A$2:$A$1542,A13) | C13: =COUNTIFS(Albums!$A$2:$A$1542,A13,Albums!$H$2:$H$1542,"Yes") | D13: =B13-C13 | E13: =IF(B13=0,0,C13/B13)
... A15: Experimental | B15: =COUNTIF(Albums!$A$2:$A$1542,A15) | C15: =COUNTIFS(Albums!$A$2:$A$1542,A15,Albums!$H$2:$H$1542,"Yes") | D15: =B15-C15 | E15: =IF(B15=0,0,C15/B15)
A16: Total | B16: =SUM(B2:B15) | C16: =SUM(C2:C15) | D16: =SUM(D2:D15) | E16: =IF(B16=0,0,C16/B16)

Sheet By Style
A1: Family | B1: Style | C1: Albums in list | D1: Owned | E1: Missing | F1: % owned
A2: Rock | B2: Alternative & Indie Rock | C2: =COUNTIF(Albums!$B$2:$B$1542,B2) | D2: =COUNTIFS(Albums!$B$2:$B$1542,B2,Albums!$H$2:$H$1542,"Yes") | E2: =C2-D2 | F2: =IF(C2=0,0,D2/C2)
A3: Rock | B3: Post-Punk & New Wave | C3: =COUNTIF(Albums!$B$2:$B$1542,B3) | D3: =COUNTIFS(Albums!$B$2:$B$1542,B3,Albums!$H$2:$H$1542,"Yes") | E3: =C3-D3 | F3: =IF(C3=0,0,D3/C3)
A4: Rock | B4: Psychedelic Rock | C4: =COUNTIF(Albums!$B$2:$B$1542,B4) | D4: =COUNTIFS(Albums!$B$2:$B$1542,B4,Albums!$H$2:$H$1542,"Yes") | E4: =C4-D4 | F4: =IF(C4=0,0,D4/C4)
A5: Rock | B5: Classic Rock & Hard Rock | C5: =COUNTIF(Albums!$B$2:$B$1542,B5) | D5: =COUNTIFS(Albums!$B$2:$B$1542,B5,Albums!$H$2:$H$1542,"Yes") | E5: =C5-D5 | F5: =IF(C5=0,0,D5/C5)
A6: Rock | B6: 1960s Beat & British Invasion | C6: =COUNTIF(Albums!$B$2:$B$1542,B6) | D6: =COUNTIFS(Albums!$B$2:$B$1542,B6,Albums!$H$2:$H$1542,"Yes") | E6: =C6-D6 | F6: =IF(C6=0,0,D6/C6)
A7: Rock | B7: Punk & Proto-Punk | C7: =COUNTIF(Albums!$B$2:$B$1542,B7) | D7: =COUNTIFS(Albums!$B$2:$B$1542,B7,Albums!$H$2:$H$1542,"Yes") | E7: =C7-D7 | F7: =IF(C7=0,0,D7/C7)
A8: Rock | B8: Grunge & 90s Alt-Metal | C8: =COUNTIF(Albums!$B$2:$B$1542,B8) | D8: =COUNTIFS(Albums!$B$2:$B$1542,B8,Albums!$H$2:$H$1542,"Yes") | E8: =C8-D8 | F8: =IF(C8=0,0,D8/C8)
A9: Rock | B9: Britpop | C9: =COUNTIF(Albums!$B$2:$B$1542,B9) | D9: =COUNTIFS(Albums!$B$2:$B$1542,B9,Albums!$H$2:$H$1542,"Yes") | E9: =C9-D9 | F9: =IF(C9=0,0,D9/C9)
A10: Rock | B10: Folk Rock & Singer-Songwriter | C10: =COUNTIF(Albums!$B$2:$B$1542,B10) | D10: =COUNTIFS(Albums!$B$2:$B$1542,B10,Albums!$H$2:$H$1542,"Yes") | E10: =C10-D10 | F10: =IF(C10=0,0,D10/C10)
A11: Rock | B11: Progressive Rock | C11: =COUNTIF(Albums!$B$2:$B$1542,B11) | D11: =COUNTIFS(Albums!$B$2:$B$1542,B11,Albums!$H$2:$H$1542,"Yes") | E11: =C11-D11 | F11: =IF(C11=0,0,D11/C11)
A12: Rock | B12: Glam & Art Rock | C12: =COUNTIF(Albums!$B$2:$B$1542,B12) | D12: =COUNTIFS(Albums!$B$2:$B$1542,B12,Albums!$H$2:$H$1542,"Yes") | E12: =C12-D12 | F12: =IF(C12=0,0,D12/C12)
A13: Rock | B13: Rock & Roll / Rockabilly | C13: =COUNTIF(Albums!$B$2:$B$1542,B13) | D13: =COUNTIFS(Albums!$B$2:$B$1542,B13,Albums!$H$2:$H$1542,"Yes") | E13: =C13-D13 | F13: =IF(C13=0,0,D13/C13)
... A98: Experimental | B98: Indeterminacy & Modern Composition | C98: =COUNTIF(Albums!$B$2:$B$1542,B98) | D98: =COUNTIFS(Albums!$B$2:$B$1542,B98,Albums!$H$2:$H$1542,"Yes") | E98: =C98-D98 | F98: =IF(C98=0,0,D98/C98)

Sheet Want List
A1: # | B1: Artist | C1: Album | D1: Year | E1: Style | F1: Family
A2: 1 | B2: Arcade Fire | C2: Funeral | D2: 2004 | E2: Alternative & Indie Rock | F2: Rock
A3: 2 | B3: Beck | C3: Odelay | D3: 1996 | E3: Alternative & Indie Rock | F3: Rock
A4: 3 | B4: Gang of Four | C4: Entertainment! | D4: 1979 | E4: Post-Punk & New Wave | F4: Rock
A5: 4 | B5: Grateful Dead | C5: American Beauty | D5: 1970 | E5: Psychedelic Rock | F5: Rock
A6: 5 | B6: Amy Winehouse | C6: Back to Black | D6: 2006 | E6: Pop | F6: Pop
A7: 6 | B7: Michael Jackson | C7: Thriller | D7: 1982 | E7: Pop | F7: Pop
A8: 7 | B8: Caetano Veloso | C8: Transa | D8: 1972 | E8: Brazilian: Bossa, Tropicália & MPB | F8: Latin
A9: 8 | B9: Jorge Ben | C9: África Brasil | D9: 1976 | E9: Brazilian: Bossa, Tropicália & MPB | F9: Latin
A10: 9 | B10: Daft Punk | C10: Discovery | D10: 2001 | E10: Synth-Pop & Electro | F10: Electronic
A11: 10 | B11: Depeche Mode | C11: Violator | D11: 1990 | E11: Synth-Pop & Electro | F11: Electronic
A12: 11 | B12: Kanye West | C12: My Beautiful Dark Twisted Fantasy | D12: 2010 | E12: Modern & Global | F12: Hip-Hop
A13: 12 | B13: The Roots | C13: Things Fall Apart | D13: 1999 | E13: Modern & Global | F13: Hip-Hop
... A19: 18 | B19: Hank Williams | C19: 40 Greatest Hits | D19: 1978 | E19: Classic Country | F19: Folk, World & Country
